{
 "cells": [
  {
   "cell_type": "code",
   "execution_count": 1,
   "metadata": {},
   "outputs": [
    {
     "name": "stderr",
     "output_type": "stream",
     "text": [
      "2023-11-20 22:53:08.827430: I tensorflow/core/util/port.cc:113] oneDNN custom operations are on. You may see slightly different numerical results due to floating-point round-off errors from different computation orders. To turn them off, set the environment variable `TF_ENABLE_ONEDNN_OPTS=0`.\n",
      "2023-11-20 22:53:08.849380: E external/local_xla/xla/stream_executor/cuda/cuda_dnn.cc:9261] Unable to register cuDNN factory: Attempting to register factory for plugin cuDNN when one has already been registered\n",
      "2023-11-20 22:53:08.849403: E external/local_xla/xla/stream_executor/cuda/cuda_fft.cc:607] Unable to register cuFFT factory: Attempting to register factory for plugin cuFFT when one has already been registered\n",
      "2023-11-20 22:53:08.849998: E external/local_xla/xla/stream_executor/cuda/cuda_blas.cc:1515] Unable to register cuBLAS factory: Attempting to register factory for plugin cuBLAS when one has already been registered\n",
      "2023-11-20 22:53:08.853456: I tensorflow/core/platform/cpu_feature_guard.cc:182] This TensorFlow binary is optimized to use available CPU instructions in performance-critical operations.\n",
      "To enable the following instructions: AVX2 AVX_VNNI FMA, in other operations, rebuild TensorFlow with the appropriate compiler flags.\n",
      "2023-11-20 22:53:09.275497: W tensorflow/compiler/tf2tensorrt/utils/py_utils.cc:38] TF-TRT Warning: Could not find TensorRT\n",
      "/home/roma/.local/lib/python3.10/site-packages/tqdm/auto.py:21: TqdmWarning: IProgress not found. Please update jupyter and ipywidgets. See https://ipywidgets.readthedocs.io/en/stable/user_install.html\n",
      "  from .autonotebook import tqdm as notebook_tqdm\n"
     ]
    }
   ],
   "source": [
    "import numpy as np\n",
    "import tensorflow as tf\n",
    "import tensorflow_datasets as tfds\n",
    "from tensorflow.keras.preprocessing.image import load_img, img_to_array\n",
    "from tensorflow.keras.layers import Dense, GlobalAveragePooling2D, Dropout\n",
    "import matplotlib as plt"
   ]
  },
  {
   "cell_type": "code",
   "execution_count": 2,
   "metadata": {},
   "outputs": [
    {
     "name": "stderr",
     "output_type": "stream",
     "text": [
      "2023-11-20 22:53:10.212110: I external/local_xla/xla/stream_executor/cuda/cuda_executor.cc:901] successful NUMA node read from SysFS had negative value (-1), but there must be at least one NUMA node, so returning NUMA node zero. See more at https://github.com/torvalds/linux/blob/v6.0/Documentation/ABI/testing/sysfs-bus-pci#L344-L355\n",
      "2023-11-20 22:53:10.230619: I external/local_xla/xla/stream_executor/cuda/cuda_executor.cc:901] successful NUMA node read from SysFS had negative value (-1), but there must be at least one NUMA node, so returning NUMA node zero. See more at https://github.com/torvalds/linux/blob/v6.0/Documentation/ABI/testing/sysfs-bus-pci#L344-L355\n",
      "2023-11-20 22:53:10.230740: I external/local_xla/xla/stream_executor/cuda/cuda_executor.cc:901] successful NUMA node read from SysFS had negative value (-1), but there must be at least one NUMA node, so returning NUMA node zero. See more at https://github.com/torvalds/linux/blob/v6.0/Documentation/ABI/testing/sysfs-bus-pci#L344-L355\n",
      "2023-11-20 22:53:10.231669: I external/local_xla/xla/stream_executor/cuda/cuda_executor.cc:901] successful NUMA node read from SysFS had negative value (-1), but there must be at least one NUMA node, so returning NUMA node zero. See more at https://github.com/torvalds/linux/blob/v6.0/Documentation/ABI/testing/sysfs-bus-pci#L344-L355\n",
      "2023-11-20 22:53:10.231750: I external/local_xla/xla/stream_executor/cuda/cuda_executor.cc:901] successful NUMA node read from SysFS had negative value (-1), but there must be at least one NUMA node, so returning NUMA node zero. See more at https://github.com/torvalds/linux/blob/v6.0/Documentation/ABI/testing/sysfs-bus-pci#L344-L355\n",
      "2023-11-20 22:53:10.231800: I external/local_xla/xla/stream_executor/cuda/cuda_executor.cc:901] successful NUMA node read from SysFS had negative value (-1), but there must be at least one NUMA node, so returning NUMA node zero. See more at https://github.com/torvalds/linux/blob/v6.0/Documentation/ABI/testing/sysfs-bus-pci#L344-L355\n",
      "2023-11-20 22:53:10.887182: I external/local_xla/xla/stream_executor/cuda/cuda_executor.cc:901] successful NUMA node read from SysFS had negative value (-1), but there must be at least one NUMA node, so returning NUMA node zero. See more at https://github.com/torvalds/linux/blob/v6.0/Documentation/ABI/testing/sysfs-bus-pci#L344-L355\n",
      "2023-11-20 22:53:10.887295: I external/local_xla/xla/stream_executor/cuda/cuda_executor.cc:901] successful NUMA node read from SysFS had negative value (-1), but there must be at least one NUMA node, so returning NUMA node zero. See more at https://github.com/torvalds/linux/blob/v6.0/Documentation/ABI/testing/sysfs-bus-pci#L344-L355\n",
      "2023-11-20 22:53:10.887353: I external/local_xla/xla/stream_executor/cuda/cuda_executor.cc:901] successful NUMA node read from SysFS had negative value (-1), but there must be at least one NUMA node, so returning NUMA node zero. See more at https://github.com/torvalds/linux/blob/v6.0/Documentation/ABI/testing/sysfs-bus-pci#L344-L355\n",
      "2023-11-20 22:53:10.887395: I tensorflow/core/common_runtime/gpu/gpu_device.cc:1929] Created device /job:localhost/replica:0/task:0/device:GPU:0 with 5745 MB memory:  -> device: 0, name: NVIDIA GeForce RTX 3060 Ti, pci bus id: 0000:01:00.0, compute capability: 8.6\n"
     ]
    }
   ],
   "source": [
    "SIZE = 224\n",
    "train = tfds.load(\"cats_vs_dogs\", split = [\"train[:100%]\"], as_supervised=True)"
   ]
  },
  {
   "cell_type": "code",
   "execution_count": 3,
   "metadata": {},
   "outputs": [],
   "source": [
    "def resize(image, label):\n",
    "  image = tf.cast(image, tf.float32)\n",
    "  image = tf.image.resize(image, (SIZE, SIZE))\n",
    "  image = image / 255.0\n",
    "  return image, label\n",
    "\n",
    "train_resized = train[0].map(resize)\n",
    "train_batches = train_resized.shuffle(1000).batch(16)"
   ]
  },
  {
   "cell_type": "code",
   "execution_count": 4,
   "metadata": {},
   "outputs": [],
   "source": [
    "base_layers = tf.keras.applications.MobileNetV2(input_shape=(SIZE, SIZE, 3), include_top=False)\n",
    "base_layers.trainable = False"
   ]
  },
  {
   "cell_type": "code",
   "execution_count": 5,
   "metadata": {},
   "outputs": [],
   "source": [
    "model = tf.keras.Sequential([base_layers, GlobalAveragePooling2D(), Dropout(0.2), Dense(1)])\n",
    "model.compile(optimizer=\"adam\", loss = tf.keras.losses.BinaryCrossentropy(from_logits=True), metrics=[\"accuracy\"])"
   ]
  },
  {
   "cell_type": "code",
   "execution_count": 6,
   "metadata": {},
   "outputs": [
    {
     "name": "stderr",
     "output_type": "stream",
     "text": [
      "2023-11-20 22:53:14.304301: I external/local_xla/xla/stream_executor/cuda/cuda_dnn.cc:454] Loaded cuDNN version 8902\n",
      "2023-11-20 22:53:14.744398: I external/local_tsl/tsl/platform/default/subprocess.cc:304] Start cannot spawn child process: No such file or directory\n",
      "2023-11-20 22:53:14.745106: I external/local_tsl/tsl/platform/default/subprocess.cc:304] Start cannot spawn child process: No such file or directory\n",
      "2023-11-20 22:53:14.745114: W external/local_xla/xla/stream_executor/gpu/asm_compiler.cc:110] Couldn't get ptxas version : FAILED_PRECONDITION: Couldn't get ptxas/nvlink version string: INTERNAL: Couldn't invoke ptxas --version\n",
      "2023-11-20 22:53:14.745634: I external/local_tsl/tsl/platform/default/subprocess.cc:304] Start cannot spawn child process: No such file or directory\n",
      "2023-11-20 22:53:14.745673: W external/local_xla/xla/stream_executor/gpu/redzone_allocator.cc:322] INTERNAL: Failed to launch ptxas\n",
      "Relying on driver to perform ptx compilation. \n",
      "Modify $PATH to customize ptxas location.\n",
      "This message will be only logged once.\n",
      "2023-11-20 22:53:14.996648: W external/local_xla/xla/service/gpu/llvm_gpu_backend/gpu_backend_lib.cc:504] Can't find libdevice directory ${CUDA_DIR}/nvvm/libdevice. This may result in compilation or runtime failures, if the program we try to run uses routines from libdevice.\n",
      "Searched for CUDA in the following directories:\n",
      "  ./cuda_sdk_lib\n",
      "  /usr/local/cuda-12.2\n",
      "  /usr/local/cuda\n",
      "  /home/roma/.local/lib/python3.10/site-packages/tensorflow/python/platform/../../../nvidia/cuda_nvcc\n",
      "  /home/roma/.local/lib/python3.10/site-packages/tensorflow/python/platform/../../../../nvidia/cuda_nvcc\n",
      "  .\n",
      "You can choose the search directory by setting xla_gpu_cuda_data_dir in HloModule's DebugOptions.  For most apps, setting the environment variable XLA_FLAGS=--xla_gpu_cuda_data_dir=/path/to/cuda will work.\n",
      "2023-11-20 22:53:15.002488: I external/local_tsl/tsl/platform/default/subprocess.cc:304] Start cannot spawn child process: No such file or directory\n",
      "2023-11-20 22:53:15.006265: I external/local_tsl/tsl/platform/default/subprocess.cc:304] Start cannot spawn child process: No such file or directory\n",
      "2023-11-20 22:53:15.006294: W external/local_xla/xla/stream_executor/gpu/asm_compiler.cc:110] Couldn't get ptxas version : FAILED_PRECONDITION: Couldn't get ptxas/nvlink version string: INTERNAL: Couldn't invoke ptxas --version\n",
      "2023-11-20 22:53:15.006703: I external/local_tsl/tsl/platform/default/subprocess.cc:304] Start cannot spawn child process: No such file or directory\n",
      "2023-11-20 22:53:15.006724: I external/local_tsl/tsl/platform/default/subprocess.cc:304] Start cannot spawn child process: No such file or directory\n",
      "2023-11-20 22:53:15.006739: W tensorflow/compiler/mlir/tools/kernel_gen/transforms/gpu_kernel_to_blob_pass.cc:191] Failed to compile generated PTX with ptxas. Falling back to compilation by driver.\n",
      "2023-11-20 22:53:15.006755: W external/local_xla/xla/stream_executor/gpu/asm_compiler.cc:110] Couldn't get ptxas version : FAILED_PRECONDITION: Couldn't get ptxas/nvlink version string: INTERNAL: Couldn't invoke ptxas --version\n",
      "2023-11-20 22:53:15.007051: I external/local_tsl/tsl/platform/default/subprocess.cc:304] Start cannot spawn child process: No such file or directory\n",
      "2023-11-20 22:53:15.007065: W external/local_xla/xla/stream_executor/gpu/asm_compiler.cc:110] Couldn't get ptxas version : FAILED_PRECONDITION: Couldn't get ptxas/nvlink version string: INTERNAL: Couldn't invoke ptxas --version\n",
      "2023-11-20 22:53:15.007151: I external/local_tsl/tsl/platform/default/subprocess.cc:304] Start cannot spawn child process: No such file or directory\n",
      "2023-11-20 22:53:15.007168: W tensorflow/compiler/mlir/tools/kernel_gen/transforms/gpu_kernel_to_blob_pass.cc:191] Failed to compile generated PTX with ptxas. Falling back to compilation by driver.\n",
      "2023-11-20 22:53:15.007353: I external/local_tsl/tsl/platform/default/subprocess.cc:304] Start cannot spawn child process: No such file or directory\n",
      "2023-11-20 22:53:15.007367: W external/local_xla/xla/stream_executor/gpu/asm_compiler.cc:110] Couldn't get ptxas version : FAILED_PRECONDITION: Couldn't get ptxas/nvlink version string: INTERNAL: Couldn't invoke ptxas --version\n",
      "2023-11-20 22:53:15.007457: I external/local_tsl/tsl/platform/default/subprocess.cc:304] Start cannot spawn child process: No such file or directory\n",
      "2023-11-20 22:53:15.007482: W tensorflow/compiler/mlir/tools/kernel_gen/transforms/gpu_kernel_to_blob_pass.cc:191] Failed to compile generated PTX with ptxas. Falling back to compilation by driver.\n",
      "2023-11-20 22:53:15.007708: I external/local_tsl/tsl/platform/default/subprocess.cc:304] Start cannot spawn child process: No such file or directory\n",
      "2023-11-20 22:53:15.007722: I external/local_tsl/tsl/platform/default/subprocess.cc:304] Start cannot spawn child process: No such file or directory\n",
      "2023-11-20 22:53:15.007726: W external/local_xla/xla/stream_executor/gpu/asm_compiler.cc:110] Couldn't get ptxas version : FAILED_PRECONDITION: Couldn't get ptxas/nvlink version string: INTERNAL: Couldn't invoke ptxas --version\n",
      "2023-11-20 22:53:15.007747: W tensorflow/compiler/mlir/tools/kernel_gen/transforms/gpu_kernel_to_blob_pass.cc:191] Failed to compile generated PTX with ptxas. Falling back to compilation by driver.\n",
      "2023-11-20 22:53:15.008024: I external/local_tsl/tsl/platform/default/subprocess.cc:304] Start cannot spawn child process: No such file or directory\n",
      "2023-11-20 22:53:15.008035: W external/local_xla/xla/stream_executor/gpu/asm_compiler.cc:110] Couldn't get ptxas version : FAILED_PRECONDITION: Couldn't get ptxas/nvlink version string: INTERNAL: Couldn't invoke ptxas --version\n",
      "2023-11-20 22:53:15.008062: I external/local_tsl/tsl/platform/default/subprocess.cc:304] Start cannot spawn child process: No such file or directory\n",
      "2023-11-20 22:53:15.008082: W tensorflow/compiler/mlir/tools/kernel_gen/transforms/gpu_kernel_to_blob_pass.cc:191] Failed to compile generated PTX with ptxas. Falling back to compilation by driver.\n",
      "2023-11-20 22:53:15.008375: I external/local_tsl/tsl/platform/default/subprocess.cc:304] Start cannot spawn child process: No such file or directory\n",
      "2023-11-20 22:53:15.008385: I external/local_tsl/tsl/platform/default/subprocess.cc:304] Start cannot spawn child process: No such file or directory\n",
      "2023-11-20 22:53:15.008391: W external/local_xla/xla/stream_executor/gpu/asm_compiler.cc:110] Couldn't get ptxas version : FAILED_PRECONDITION: Couldn't get ptxas/nvlink version string: INTERNAL: Couldn't invoke ptxas --version\n",
      "2023-11-20 22:53:15.008403: W tensorflow/compiler/mlir/tools/kernel_gen/transforms/gpu_kernel_to_blob_pass.cc:191] Failed to compile generated PTX with ptxas. Falling back to compilation by driver.\n",
      "2023-11-20 22:53:15.008711: I external/local_tsl/tsl/platform/default/subprocess.cc:304] Start cannot spawn child process: No such file or directory\n",
      "2023-11-20 22:53:15.008722: I external/local_tsl/tsl/platform/default/subprocess.cc:304] Start cannot spawn child process: No such file or directory\n",
      "2023-11-20 22:53:15.008729: W external/local_xla/xla/stream_executor/gpu/asm_compiler.cc:110] Couldn't get ptxas version : FAILED_PRECONDITION: Couldn't get ptxas/nvlink version string: INTERNAL: Couldn't invoke ptxas --version\n",
      "2023-11-20 22:53:15.008738: W tensorflow/compiler/mlir/tools/kernel_gen/transforms/gpu_kernel_to_blob_pass.cc:191] Failed to compile generated PTX with ptxas. Falling back to compilation by driver.\n",
      "2023-11-20 22:53:15.009078: I external/local_tsl/tsl/platform/default/subprocess.cc:304] Start cannot spawn child process: No such file or directory\n",
      "2023-11-20 22:53:15.009093: W external/local_xla/xla/stream_executor/gpu/asm_compiler.cc:110] Couldn't get ptxas version : FAILED_PRECONDITION: Couldn't get ptxas/nvlink version string: INTERNAL: Couldn't invoke ptxas --version\n",
      "2023-11-20 22:53:15.009095: I external/local_tsl/tsl/platform/default/subprocess.cc:304] Start cannot spawn child process: No such file or directory\n",
      "2023-11-20 22:53:15.009120: W tensorflow/compiler/mlir/tools/kernel_gen/transforms/gpu_kernel_to_blob_pass.cc:191] Failed to compile generated PTX with ptxas. Falling back to compilation by driver.\n",
      "2023-11-20 22:53:15.009416: I external/local_tsl/tsl/platform/default/subprocess.cc:304] Start cannot spawn child process: No such file or directory\n",
      "2023-11-20 22:53:15.009432: W tensorflow/compiler/mlir/tools/kernel_gen/transforms/gpu_kernel_to_blob_pass.cc:191] Failed to compile generated PTX with ptxas. Falling back to compilation by driver.\n",
      "2023-11-20 22:53:15.269297: I external/local_tsl/tsl/platform/default/subprocess.cc:304] Start cannot spawn child process: No such file or directory\n",
      "2023-11-20 22:53:15.269324: W external/local_xla/xla/stream_executor/gpu/asm_compiler.cc:110] Couldn't get ptxas version : FAILED_PRECONDITION: Couldn't get ptxas/nvlink version string: INTERNAL: Couldn't invoke ptxas --version\n",
      "2023-11-20 22:53:15.269891: I external/local_tsl/tsl/platform/default/subprocess.cc:304] Start cannot spawn child process: No such file or directory\n",
      "2023-11-20 22:53:15.269943: W tensorflow/compiler/mlir/tools/kernel_gen/transforms/gpu_kernel_to_blob_pass.cc:191] Failed to compile generated PTX with ptxas. Falling back to compilation by driver.\n",
      "2023-11-20 22:53:15.306675: I external/local_tsl/tsl/platform/default/subprocess.cc:304] Start cannot spawn child process: No such file or directory\n",
      "2023-11-20 22:53:15.306700: W external/local_xla/xla/stream_executor/gpu/asm_compiler.cc:110] Couldn't get ptxas version : FAILED_PRECONDITION: Couldn't get ptxas/nvlink version string: INTERNAL: Couldn't invoke ptxas --version\n",
      "2023-11-20 22:53:15.307078: I external/local_tsl/tsl/platform/default/subprocess.cc:304] Start cannot spawn child process: No such file or directory\n",
      "2023-11-20 22:53:15.307101: W tensorflow/compiler/mlir/tools/kernel_gen/transforms/gpu_kernel_to_blob_pass.cc:191] Failed to compile generated PTX with ptxas. Falling back to compilation by driver.\n",
      "2023-11-20 22:53:15.410966: W external/local_xla/xla/service/gpu/llvm_gpu_backend/gpu_backend_lib.cc:542] libdevice is required by this HLO module but was not found at ./libdevice.10.bc\n",
      "error: libdevice not found at ./libdevice.10.bc\n",
      "2023-11-20 22:53:15.411104: E tensorflow/compiler/mlir/tools/kernel_gen/tf_framework_c_interface.cc:207] INTERNAL: Generating device code failed.\n",
      "2023-11-20 22:53:15.411458: W tensorflow/core/framework/op_kernel.cc:1827] UNKNOWN: JIT compilation failed.\n"
     ]
    },
    {
     "ename": "UnknownError",
     "evalue": "Graph execution error:\n\nDetected at node binary_crossentropy/logistic_loss/Exp defined at (most recent call last):\n  File \"/usr/lib/python3.10/runpy.py\", line 196, in _run_module_as_main\n\n  File \"/usr/lib/python3.10/runpy.py\", line 86, in _run_code\n\n  File \"/home/roma/.local/lib/python3.10/site-packages/ipykernel_launcher.py\", line 17, in <module>\n\n  File \"/home/roma/.local/lib/python3.10/site-packages/traitlets/config/application.py\", line 1053, in launch_instance\n\n  File \"/home/roma/.local/lib/python3.10/site-packages/ipykernel/kernelapp.py\", line 737, in start\n\n  File \"/home/roma/.local/lib/python3.10/site-packages/tornado/platform/asyncio.py\", line 195, in start\n\n  File \"/usr/lib/python3.10/asyncio/base_events.py\", line 603, in run_forever\n\n  File \"/usr/lib/python3.10/asyncio/base_events.py\", line 1909, in _run_once\n\n  File \"/usr/lib/python3.10/asyncio/events.py\", line 80, in _run\n\n  File \"/home/roma/.local/lib/python3.10/site-packages/ipykernel/kernelbase.py\", line 524, in dispatch_queue\n\n  File \"/home/roma/.local/lib/python3.10/site-packages/ipykernel/kernelbase.py\", line 513, in process_one\n\n  File \"/home/roma/.local/lib/python3.10/site-packages/ipykernel/kernelbase.py\", line 418, in dispatch_shell\n\n  File \"/home/roma/.local/lib/python3.10/site-packages/ipykernel/kernelbase.py\", line 758, in execute_request\n\n  File \"/home/roma/.local/lib/python3.10/site-packages/ipykernel/ipkernel.py\", line 426, in do_execute\n\n  File \"/home/roma/.local/lib/python3.10/site-packages/ipykernel/zmqshell.py\", line 549, in run_cell\n\n  File \"/home/roma/.local/lib/python3.10/site-packages/IPython/core/interactiveshell.py\", line 3046, in run_cell\n\n  File \"/home/roma/.local/lib/python3.10/site-packages/IPython/core/interactiveshell.py\", line 3101, in _run_cell\n\n  File \"/home/roma/.local/lib/python3.10/site-packages/IPython/core/async_helpers.py\", line 129, in _pseudo_sync_runner\n\n  File \"/home/roma/.local/lib/python3.10/site-packages/IPython/core/interactiveshell.py\", line 3306, in run_cell_async\n\n  File \"/home/roma/.local/lib/python3.10/site-packages/IPython/core/interactiveshell.py\", line 3488, in run_ast_nodes\n\n  File \"/home/roma/.local/lib/python3.10/site-packages/IPython/core/interactiveshell.py\", line 3548, in run_code\n\n  File \"/tmp/ipykernel_133698/2401243862.py\", line 1, in <module>\n\n  File \"/home/roma/.local/lib/python3.10/site-packages/keras/src/utils/traceback_utils.py\", line 65, in error_handler\n\n  File \"/home/roma/.local/lib/python3.10/site-packages/keras/src/engine/training.py\", line 1807, in fit\n\n  File \"/home/roma/.local/lib/python3.10/site-packages/keras/src/engine/training.py\", line 1401, in train_function\n\n  File \"/home/roma/.local/lib/python3.10/site-packages/keras/src/engine/training.py\", line 1384, in step_function\n\n  File \"/home/roma/.local/lib/python3.10/site-packages/keras/src/engine/training.py\", line 1373, in run_step\n\n  File \"/home/roma/.local/lib/python3.10/site-packages/keras/src/engine/training.py\", line 1151, in train_step\n\n  File \"/home/roma/.local/lib/python3.10/site-packages/keras/src/engine/training.py\", line 1209, in compute_loss\n\n  File \"/home/roma/.local/lib/python3.10/site-packages/keras/src/engine/compile_utils.py\", line 277, in __call__\n\n  File \"/home/roma/.local/lib/python3.10/site-packages/keras/src/losses.py\", line 143, in __call__\n\n  File \"/home/roma/.local/lib/python3.10/site-packages/keras/src/losses.py\", line 270, in call\n\n  File \"/home/roma/.local/lib/python3.10/site-packages/keras/src/losses.py\", line 2532, in binary_crossentropy\n\n  File \"/home/roma/.local/lib/python3.10/site-packages/keras/src/backend.py\", line 5822, in binary_crossentropy\n\nJIT compilation failed.\n\t [[{{node binary_crossentropy/logistic_loss/Exp}}]] [Op:__inference_train_function_8758]",
     "output_type": "error",
     "traceback": [
      "\u001b[0;31m---------------------------------------------------------------------------\u001b[0m",
      "\u001b[0;31mUnknownError\u001b[0m                              Traceback (most recent call last)",
      "\u001b[1;32m/home/roma/Документы/code/python/tensorflow.ipynb Cell 6\u001b[0m line \u001b[0;36m1\n\u001b[0;32m----> <a href='vscode-notebook-cell:/home/roma/%D0%94%D0%BE%D0%BA%D1%83%D0%BC%D0%B5%D0%BD%D1%82%D1%8B/code/python/tensorflow.ipynb#W5sZmlsZQ%3D%3D?line=0'>1</a>\u001b[0m model\u001b[39m.\u001b[39;49mfit(train_batches, epochs\u001b[39m=\u001b[39;49m\u001b[39m1\u001b[39;49m)\n",
      "File \u001b[0;32m~/.local/lib/python3.10/site-packages/keras/src/utils/traceback_utils.py:70\u001b[0m, in \u001b[0;36mfilter_traceback.<locals>.error_handler\u001b[0;34m(*args, **kwargs)\u001b[0m\n\u001b[1;32m     67\u001b[0m     filtered_tb \u001b[39m=\u001b[39m _process_traceback_frames(e\u001b[39m.\u001b[39m__traceback__)\n\u001b[1;32m     68\u001b[0m     \u001b[39m# To get the full stack trace, call:\u001b[39;00m\n\u001b[1;32m     69\u001b[0m     \u001b[39m# `tf.debugging.disable_traceback_filtering()`\u001b[39;00m\n\u001b[0;32m---> 70\u001b[0m     \u001b[39mraise\u001b[39;00m e\u001b[39m.\u001b[39mwith_traceback(filtered_tb) \u001b[39mfrom\u001b[39;00m \u001b[39mNone\u001b[39;00m\n\u001b[1;32m     71\u001b[0m \u001b[39mfinally\u001b[39;00m:\n\u001b[1;32m     72\u001b[0m     \u001b[39mdel\u001b[39;00m filtered_tb\n",
      "File \u001b[0;32m~/.local/lib/python3.10/site-packages/tensorflow/python/eager/execute.py:53\u001b[0m, in \u001b[0;36mquick_execute\u001b[0;34m(op_name, num_outputs, inputs, attrs, ctx, name)\u001b[0m\n\u001b[1;32m     51\u001b[0m \u001b[39mtry\u001b[39;00m:\n\u001b[1;32m     52\u001b[0m   ctx\u001b[39m.\u001b[39mensure_initialized()\n\u001b[0;32m---> 53\u001b[0m   tensors \u001b[39m=\u001b[39m pywrap_tfe\u001b[39m.\u001b[39mTFE_Py_Execute(ctx\u001b[39m.\u001b[39m_handle, device_name, op_name,\n\u001b[1;32m     54\u001b[0m                                       inputs, attrs, num_outputs)\n\u001b[1;32m     55\u001b[0m \u001b[39mexcept\u001b[39;00m core\u001b[39m.\u001b[39m_NotOkStatusException \u001b[39mas\u001b[39;00m e:\n\u001b[1;32m     56\u001b[0m   \u001b[39mif\u001b[39;00m name \u001b[39mis\u001b[39;00m \u001b[39mnot\u001b[39;00m \u001b[39mNone\u001b[39;00m:\n",
      "\u001b[0;31mUnknownError\u001b[0m: Graph execution error:\n\nDetected at node binary_crossentropy/logistic_loss/Exp defined at (most recent call last):\n  File \"/usr/lib/python3.10/runpy.py\", line 196, in _run_module_as_main\n\n  File \"/usr/lib/python3.10/runpy.py\", line 86, in _run_code\n\n  File \"/home/roma/.local/lib/python3.10/site-packages/ipykernel_launcher.py\", line 17, in <module>\n\n  File \"/home/roma/.local/lib/python3.10/site-packages/traitlets/config/application.py\", line 1053, in launch_instance\n\n  File \"/home/roma/.local/lib/python3.10/site-packages/ipykernel/kernelapp.py\", line 737, in start\n\n  File \"/home/roma/.local/lib/python3.10/site-packages/tornado/platform/asyncio.py\", line 195, in start\n\n  File \"/usr/lib/python3.10/asyncio/base_events.py\", line 603, in run_forever\n\n  File \"/usr/lib/python3.10/asyncio/base_events.py\", line 1909, in _run_once\n\n  File \"/usr/lib/python3.10/asyncio/events.py\", line 80, in _run\n\n  File \"/home/roma/.local/lib/python3.10/site-packages/ipykernel/kernelbase.py\", line 524, in dispatch_queue\n\n  File \"/home/roma/.local/lib/python3.10/site-packages/ipykernel/kernelbase.py\", line 513, in process_one\n\n  File \"/home/roma/.local/lib/python3.10/site-packages/ipykernel/kernelbase.py\", line 418, in dispatch_shell\n\n  File \"/home/roma/.local/lib/python3.10/site-packages/ipykernel/kernelbase.py\", line 758, in execute_request\n\n  File \"/home/roma/.local/lib/python3.10/site-packages/ipykernel/ipkernel.py\", line 426, in do_execute\n\n  File \"/home/roma/.local/lib/python3.10/site-packages/ipykernel/zmqshell.py\", line 549, in run_cell\n\n  File \"/home/roma/.local/lib/python3.10/site-packages/IPython/core/interactiveshell.py\", line 3046, in run_cell\n\n  File \"/home/roma/.local/lib/python3.10/site-packages/IPython/core/interactiveshell.py\", line 3101, in _run_cell\n\n  File \"/home/roma/.local/lib/python3.10/site-packages/IPython/core/async_helpers.py\", line 129, in _pseudo_sync_runner\n\n  File \"/home/roma/.local/lib/python3.10/site-packages/IPython/core/interactiveshell.py\", line 3306, in run_cell_async\n\n  File \"/home/roma/.local/lib/python3.10/site-packages/IPython/core/interactiveshell.py\", line 3488, in run_ast_nodes\n\n  File \"/home/roma/.local/lib/python3.10/site-packages/IPython/core/interactiveshell.py\", line 3548, in run_code\n\n  File \"/tmp/ipykernel_133698/2401243862.py\", line 1, in <module>\n\n  File \"/home/roma/.local/lib/python3.10/site-packages/keras/src/utils/traceback_utils.py\", line 65, in error_handler\n\n  File \"/home/roma/.local/lib/python3.10/site-packages/keras/src/engine/training.py\", line 1807, in fit\n\n  File \"/home/roma/.local/lib/python3.10/site-packages/keras/src/engine/training.py\", line 1401, in train_function\n\n  File \"/home/roma/.local/lib/python3.10/site-packages/keras/src/engine/training.py\", line 1384, in step_function\n\n  File \"/home/roma/.local/lib/python3.10/site-packages/keras/src/engine/training.py\", line 1373, in run_step\n\n  File \"/home/roma/.local/lib/python3.10/site-packages/keras/src/engine/training.py\", line 1151, in train_step\n\n  File \"/home/roma/.local/lib/python3.10/site-packages/keras/src/engine/training.py\", line 1209, in compute_loss\n\n  File \"/home/roma/.local/lib/python3.10/site-packages/keras/src/engine/compile_utils.py\", line 277, in __call__\n\n  File \"/home/roma/.local/lib/python3.10/site-packages/keras/src/losses.py\", line 143, in __call__\n\n  File \"/home/roma/.local/lib/python3.10/site-packages/keras/src/losses.py\", line 270, in call\n\n  File \"/home/roma/.local/lib/python3.10/site-packages/keras/src/losses.py\", line 2532, in binary_crossentropy\n\n  File \"/home/roma/.local/lib/python3.10/site-packages/keras/src/backend.py\", line 5822, in binary_crossentropy\n\nJIT compilation failed.\n\t [[{{node binary_crossentropy/logistic_loss/Exp}}]] [Op:__inference_train_function_8758]"
     ]
    }
   ],
   "source": [
    "model.fit(train_batches, epochs=1)"
   ]
  },
  {
   "cell_type": "code",
   "execution_count": null,
   "metadata": {},
   "outputs": [
    {
     "name": "stdout",
     "output_type": "stream",
     "text": [
      "1/1 [==============================] - 0s 344ms/step\n"
     ]
    },
    {
     "data": {
      "text/plain": [
       "array([[-0.28876877]], dtype=float32)"
      ]
     },
     "execution_count": 28,
     "metadata": {},
     "output_type": "execute_result"
    }
   ],
   "source": [
    "img = tf.keras.utils.load_img(\"cat.jpg\")\n",
    "img_array = img_to_array(img)\n",
    "img_resized, _ = resize(img_array, _)\n",
    "img_expended = np.expand_dims(img_resized, axis=0)\n",
    "model.predict(img_expended)"
   ]
  }
 ],
 "metadata": {
  "kernelspec": {
   "display_name": "Python 3",
   "language": "python",
   "name": "python3"
  },
  "language_info": {
   "codemirror_mode": {
    "name": "ipython",
    "version": 3
   },
   "file_extension": ".py",
   "mimetype": "text/x-python",
   "name": "python",
   "nbconvert_exporter": "python",
   "pygments_lexer": "ipython3",
   "version": "3.10.6"
  }
 },
 "nbformat": 4,
 "nbformat_minor": 2
}
